File: aa-raman-551.txt
#Acq. time (s)=	5
#Accumulations=	5
#Range (cm-�)=	100...1000
#Windows=	2
#Autofocus=	Off
#AutoExposure=	Off
#Spike filter=	Multiple accum.
#Delay time (s)=	0
#Binning=	1
#Readout mode=	Signal
#DeNoise=	Standard
#ICS correction=	Off
#Dark correction=	Off
#Inst. Process=	Off
#Detector temperature (�C)=	-65
#Instrument=	ARAMIS
#Detector=	Andor CCD
#Objective=	x100
#Grating=	2400
#Filter=	100%
#Laser (nm)=	442
#Slit=	100
#Location=	Micro
#Range=	Visible
#StageXY=	Marzhauser
#X (�m)=	758
#Y (�m)=	51.9
#Full time(s)=	55
#Project=
#Sample=
#Site=
#Title=	aa-raman-551
#Remark=
#Date=	17.11.2024 17:03
#Acquired=	17.11.2024 17:03:48
100.001	-2.68388
100.932	-2.57093
101.861	-2.73123
102.792	-2.94482
103.721	-3.0863
104.65	-3.1175
105.58	-2.69054
106.509	-2.13025
107.438	-1.81047
108.368	-1.32103
109.297	-0.630133
110.225	0.345142
111.154	1.64799
112.082	3.19907
113.012	4.98067
113.94	6.98712
114.868	9.34201
115.796	12.3335
116.724	16.1506
117.652	19.8616
118.58	23.8521
119.508	28.3582
120.436	33.2142
121.363	38.3961
122.291	43.9368
123.217	49.6614
124.144	55.9761
125.071	62.4078
125.999	68.4446
126.924	74.6761
127.851	80.7643
128.778	86.6611
129.704	92.7343
130.631	98.3735
131.557	103.76
132.483	108.702
133.409	113.781
134.334	118.591
135.261	123.478
136.185	127.375
137.112	132.02
138.036	136.417
138.961	141.08
139.887	146.272
140.812	152.438
141.736	158.931
142.662	168.206
143.586	177.4
144.51	188.655
145.434	199.698
146.36	211.468
147.284	221.678
148.208	232.422
149.132	240.318
150.055	245.283
150.979	246.673
151.902	243.12
152.826	241.074
153.749	238.433
154.673	236.491
155.596	234.363
156.518	230.796
157.441	226.885
158.364	223.132
159.287	222.631
160.21	221.102
161.131	218.993
162.053	216.968
162.976	215.378
163.897	214.895
164.82	213.814
165.742	212.823
166.663	212.247
167.585	212.493
168.506	213.044
169.428	214.019
170.348	215.432
171.269	217.359
172.191	219.453
173.111	221.499
174.033	223.89
174.953	225.74
175.873	227.362
176.793	228.904
177.714	230.389
178.634	232.063
179.554	233.025
180.474	234.65
181.393	236.294
182.313	237.168
183.232	239.348
184.152	241.65
185.071	245.775
185.99	252.769
186.909	261.847
187.828	273.271
188.747	284.012
189.666	292.552
190.585	300.75
191.504	306.021
192.421	306.117
193.34	296.477
194.258	286.925
195.177	277.413
196.093	268.674
197.012	261.259
197.93	255.393
198.847	250.821
199.765	247.265
200.681	244.711
201.599	243.692
202.515	241.36
203.433	243.665
204.349	248.343
205.267	251.661
206.183	254.86
207.099	257.652
208.016	259.32
208.932	260.839
209.848	261.308
210.764	260.857
211.681	257.354
212.596	254.6
213.512	252.319
214.427	250.369
215.342	247.333
216.258	246.132
217.173	245.189
218.088	244.678
219.003	244.177
219.918	244.762
220.833	246.027
221.747	246.401
222.662	246.219
223.577	246.117
224.49	246.177
225.404	246.103
226.318	245.852
227.233	245.732
228.145	244.969
229.06	244.037
229.974	242.681
230.886	241.02
231.8	238.252
232.714	234.109
233.626	229.897
234.54	225.728
235.452	221.525
236.366	217.268
237.278	214.042
238.19	210.99
239.103	208.006
240.015	205.466
240.926	202.71
241.839	200.865
242.751	199.439
243.662	198.49
244.574	198.055
245.487	198.2
246.398	198.673
247.309	198.394
248.22	197.899
249.131	196.701
250.042	196.084
250.953	196.178
251.864	196.504
252.774	196.636
253.685	196.913
254.595	197.15
255.506	198.121
256.415	199.424
257.325	200.026
258.235	200.221
259.146	199.613
260.054	199.199
260.964	198.937
261.874	198.44
262.782	198.345
263.692	198.666
264.602	198.705
265.51	198.927
266.42	199.264
267.328	199.117
268.237	199.135
269.145	199.127
270.054	198.867
270.962	198.774
271.87	199.055
272.779	200.079
273.686	201.395
274.594	202.109
275.501	203.378
276.41	204.727
277.317	204.856
278.224	206.07
279.131	206.576
280.038	207.934
280.945	209.807
281.852	212.108
282.758	215.681
283.665	218.566
284.572	220.764
285.478	223.334
286.385	225.089
287.291	226.192
288.197	227
289.104	227.779
290.01	228.755
290.914	230.11
291.82	230.807
292.726	231.954
293.63	233.163
294.536	234.363
295.442	235.712
296.346	237.171
297.252	238.945
298.156	240.927
299.061	243.488
299.965	246.455
300.87	249.828
301.774	252.883
302.679	256.059
303.582	259.515
304.486	261.946
305.391	263.812
306.294	266.188
307.197	268.321
308.1	271.014
309.005	274.454
309.908	278.12
310.811	282.509
311.714	285.168
312.617	287.731
313.519	289.074
314.422	289.385
315.325	289.102
316.227	288.223
317.13	287.344
318.032	286.212
318.934	283.315
319.836	281.719
320.739	280.457
321.639	279.48
322.541	278.862
323.443	278.85
324.345	279.67
325.245	281.386
326.147	283.619
327.048	285.005
327.949	287.527
328.85	289.914
329.75	291.044
330.651	293.408
331.551	296.598
332.452	301.015
333.352	304.823
334.253	309.705
335.152	315.082
336.052	321.438
336.952	325.371
337.852	327.853
338.751	328.995
339.65	330.113
340.551	331.678
341.449	334.953
342.348	327.536
343.247	331.513
344.146	335.467
345.045	347.052
345.943	353.566
346.842	357.441
347.74	360.773
348.638	363.233
349.537	364.329
350.435	365.393
351.333	367.54
352.231	369.365
353.128	371.279
354.026	373.148
354.923	375.697
355.821	377.38
356.717	380.131
357.615	383.151
358.513	387.27
359.409	391.651
360.306	397.84
361.202	403.982
362.099	412.499
362.995	421.806
363.892	433.506
364.788	445.475
365.685	459.12
366.58	473.675
367.475	489.62
368.372	510.322
369.267	534.14
370.162	560.752
371.057	596.074
371.954	635.052
372.849	692.527
373.744	777.492
374.638	857.55
375.533	931.863
376.428	983.777
377.322	1014.91
378.217	1042.86
379.111	1074.94
380.006	1172.57
380.9	1449.18
381.794	2210
382.688	3610.75
383.581	4781.5
384.475	4754.75
385.368	3581.5
386.262	2055.5
387.155	1178.26
388.048	866.543
388.942	785.564
389.834	735.921
390.727	712.881
391.619	717.53
392.513	742.845
393.406	792.397
394.297	873.967
395.189	983.13
396.082	1125.81
396.974	1298.45
397.866	1597.09
398.758	2090.33
399.649	2870.64
400.54	4031.92
401.433	5780.18
402.324	7580
403.215	8793.5
404.106	8502.75
404.996	6899.73
405.887	5039.68
406.779	3537.54
407.67	2667.98
408.561	2079.92
409.451	1727.52
410.341	1496.83
411.23	1320.92
412.12	1204.28
413.011	1096.3
413.901	1005.45
414.791	931.605
415.681	873.879
416.569	833.035
417.459	802.02
418.349	792.421
419.237	781.283
420.126	772.107
421.016	759.201
421.904	749.433
422.793	737.821
423.681	722.005
424.57	709.103
425.458	697.313
426.347	688.379
427.235	683.458
428.122	679.125
429.011	675.559
429.898	673.063
430.785	671.753
431.674	671.879
432.561	672.278
433.448	674.506
434.335	677.392
435.222	680.177
436.109	683.794
436.996	688.231
437.882	692.22
438.769	698.153
439.656	705.874
440.542	714.813
441.428	726.043
442.315	738.132
443.201	751.817
444.087	767.533
444.973	783.903
445.859	801.428
446.744	819.047
447.63	839.716
448.515	861.631
449.4	881.855
450.285	896.643
451.171	907.183
452.055	915.06
452.941	912.542
453.824	901.872
454.71	885.396
455.594	857.006
456.479	834.998
457.362	811.333
458.246	789.129
459.131	767.594
460.014	752.184
460.898	732.788
461.782	714.86
462.666	699.398
463.549	683.328
464.432	667.435
465.315	653.356
466.198	637.615
467.08	620.41
467.963	599.002
468.847	573.995
469.729	542.332
470.611	507.726
471.494	465.835
472.376	420.551
473.258	375.326
474.141	332.599
475.023	294.505
475.905	259.599
476.786	231.705
477.668	212.18
478.55	202.53
479.43	205.089
480.312	201.633
481.193	200.489
482.074	199.532
482.955	199.402
483.835	199.626
484.717	200.565
485.596	202.364
486.478	202.918
487.358	204.106
488.237	206.936
489.118	209.009
489.998	210.924
490.877	213.468
491.758	215.929
492.637	218.04
493.517	220.199
494.396	221.88
495.275	224.308
496.154	226.657
497.033	230.281
497.912	233.746
498.791	237.958
499.669	241.922
500.548	246.388
501.427	251.613
502.305	256.981
503.184	262.666
504.062	270.906
504.94	281.462
505.817	292.24
506.695	304.335
507.574	321.024
508.452	340.022
509.328	367.085
510.206	399.947
511.082	446.501
511.96	506.284
512.838	582.653
513.714	706.84
514.592	876.274
515.468	1231.15
516.344	1846.38
517.221	3081.5
518.097	4785.75
518.972	6042
519.85	6010.75
520.725	4668.17
521.601	3059.89
522.478	1898.8
523.353	1265.77
524.228	941.736
525.104	756.356
525.979	646.315
526.854	562.688
527.729	506.94
528.604	467.534
529.479	433.054
530.354	402.969
531.228	380.581
532.103	363.491
532.978	350.414
533.851	341.83
534.725	330.196
535.6	326.584
536.474	321.679
537.347	318.182
538.221	314.113
539.095	311.931
539.968	310.48
540.842	309.816
541.714	310.549
542.588	312.03
543.46	314.118
544.334	315.919
545.206	316.666
546.08	318.295
546.952	320.092
547.824	322.348
548.697	324.69
549.569	327.857
550.441	331.327
551.314	333.911
552.185	336.429
553.057	339.305
553.928	342.669
554.8	346.554
555.671	350.439
556.542	355.053
557.414	360.75
558.285	366.951
559.156	374.835
560.027	384.755
560.898	395.648
561.769	407.776
562.639	420.026
563.509	437.758
564.379	454.206
565.25	475.594
566.12	494.096
566.989	522.526
567.86	541.122
568.73	556.356
569.599	557.802
570.469	536.108
571.338	492.266
572.208	452.533
573.076	418.026
573.946	389.011
574.814	368.684
575.683	357.734
576.552	349.848
577.42	345.002
578.288	346.684
579.158	348.35
580.026	352.214
580.894	356.787
581.762	362.146
582.629	368.381
583.497	375.908
584.366	383.796
585.234	390.613
586.101	396.222
586.968	399.304
587.836	400.193
588.701	399.773
589.569	396.773
590.436	389.492
591.303	385.223
592.17	385.846
593.037	386.354
593.902	390.75
594.769	394.956
595.635	398.135
596.501	402.457
597.367	404.419
598.234	406.463
599.099	406.221
599.965	404.371
600.83	399.649
601.696	391.472
602.561	383.417
603.427	374.652
604.291	366.191
605.156	359.7
606.022	353.506
606.886	347.681
607.75	346.754
608.615	343.64
609.48	341.292
610.344	339.83
611.208	337.975
612.072	335.89
612.936	334.49
613.8	332.753
614.664	330.642
615.527	327.139
616.391	322.518
617.254	316.797
618.118	310.632
618.981	302.2
619.843	295.513
620.706	287.166
621.569	279.725
622.432	272.526
623.294	266.364
624.157	261.162
625.02	257.037
625.881	255.241
626.744	252.158
627.607	249.487
628.468	247.703
629.331	246.15
630.192	243.564
631.053	240.48
631.915	236.357
632.776	233.245
633.638	230.245
634.499	227.194
635.359	224.171
636.22	221.041
637.082	218.097
637.942	214.359
638.803	210.787
639.663	206.699
640.523	202.511
641.383	198.334
642.243	193.812
643.103	189.348
643.963	185.067
644.823	180.824
645.683	176.73
646.543	172.576
647.402	168.905
648.262	165.648
649.12	163.057
649.98	160.486
650.839	158.587
651.698	156.752
652.556	154.958
653.415	153.635
654.275	152.826
655.132	151.79
655.991	151.063
656.849	150.331
657.708	149.287
658.565	148.628
659.424	147.836
660.281	148.187
661.138	148.685
661.997	149.713
662.854	151.134
663.71	152.586
664.567	154.324
665.426	157.423
666.282	161.193
667.139	165.615
667.996	170.445
668.852	175.507
669.709	180.122
670.565	184.625
671.421	188.909
672.278	192.224
673.134	194.547
673.99	197.783
674.846	197.771
675.702	196.918
676.556	196.094
677.412	194.004
678.268	191.229
679.124	188.048
679.978	183.425
680.834	178.559
681.689	174.217
682.543	169.678
683.399	166.807
684.252	164.357
685.108	162.294
685.961	161.206
686.817	160.707
687.67	161.556
688.524	163.328
689.379	165.542
690.232	168.647
691.085	172.51
691.94	176.597
692.793	182.001
693.646	189.092
694.5	195.731
695.353	202.15
696.205	210.171
697.058	218.778
697.911	227.238
698.764	234.945
699.617	243.267
700.469	249.243
701.322	254.36
702.174	257.195
703.027	257.013
703.879	254.561
704.731	249.654
705.582	243.325
706.434	236.625
707.286	229.674
708.137	221.823
708.989	214.161
709.84	206.354
710.691	198.807
711.543	192.908
712.393	188.711
713.244	186.606
714.094	185.975
714.946	188.607
715.796	190.559
716.646	193.538
717.497	196.37
718.347	201.243
719.196	205.161
720.046	208.705
720.897	211.351
721.747	213.091
722.596	214.407
723.445	214.629
724.295	213.715
725.144	213.479
725.993	213.03
726.842	213.3
727.691	214.133
728.54	215.201
729.389	218.045
730.238	223.86
731.085	229.403
731.934	234.681
732.782	241.195
733.631	246.818
734.478	252.465
735.326	258.079
736.175	263.151
737.022	267.518
737.87	271.25
738.716	274.329
739.565	277.793
740.411	281.128
741.259	283.653
742.106	288.203
742.953	294.057
743.8	300.373
744.646	308.621
745.494	318.807
746.34	329.938
747.186	342.689
748.032	356.298
748.878	370.329
749.724	383.776
750.571	397.417
751.417	409.225
752.262	419.918
753.108	428.474
753.953	434.951
754.799	438.006
755.644	438.96
756.488	435.22
757.333	429.486
758.178	422.105
759.024	410.674
759.869	398.121
760.712	384.878
761.557	370.735
762.402	356.045
763.245	341.597
764.09	325.855
764.933	310.704
765.778	295.439
766.621	280.927
767.466	268.111
768.308	255.353
769.153	244.478
769.996	234.693
770.84	227.692
771.683	222.8
772.525	217.79
773.368	217.158
774.212	217.963
775.054	223.321
775.896	230.599
776.739	237.526
777.581	246.579
778.423	252.433
779.265	257.079
780.107	259.643
780.949	259.726
781.791	255.374
782.633	251.742
783.475	247.74
784.317	243.783
785.158	240.008
785.998	235.995
786.84	232.316
787.681	227.186
788.521	223.079
789.363	219.756
790.204	215.724
791.044	211.46
791.885	207.269
792.724	203.082
793.565	199.292
794.405	195.856
795.246	192.607
796.085	189.306
796.926	186.509
797.765	183.864
798.604	181.962
799.443	180.796
800.284	180.276
801.123	180.472
801.962	181.111
802.801	183.263
803.639	184.939
804.478	186.723
805.317	189.518
806.155	192.656
806.994	196.345
807.832	200.294
808.671	204.47
809.509	207.509
810.347	213.222
811.186	219.129
812.024	225.298
812.86	231.694
813.698	238.521
814.536	244.979
815.374	250.99
816.211	254.686
817.048	259.091
817.885	263.023
818.722	266.104
819.558	267.777
820.396	268.217
821.232	267.188
822.069	262.342
822.905	257.362
823.741	251.227
824.578	242.651
825.414	235.173
826.249	226.593
827.086	216.066
827.922	204.767
828.757	194.208
829.592	184.31
830.428	175.327
831.263	167.601
832.098	160.898
832.933	156.803
833.768	152.654
834.603	148.52
835.438	144.658
836.273	141.619
837.107	138.865
837.941	136.931
838.775	135.062
839.61	133.565
840.444	132.423
841.277	131.554
842.112	130.902
842.946	130.117
843.779	129.69
844.613	128.941
845.446	128.342
846.28	127.653
847.112	126.908
847.946	126.665
848.779	126.258
849.611	125.233
850.445	123.642
851.277	122.597
852.109	121.67
852.943	120.975
853.775	120.66
854.607	120.891
855.439	120.893
856.27	121.096
857.102	121.078
857.934	121.21
858.766	120.876
859.597	120.901
860.429	121.645
861.26	122.45
862.092	122.539
862.923	122.964
863.754	122.927
864.584	122.611
865.415	122.1
866.246	120.955
867.077	119.918
867.907	118.989
868.738	118.213
869.567	117.612
870.398	117.599
871.227	117.445
872.058	117.049
872.887	117.013
873.717	116.572
874.546	116.1
875.377	115.156
876.206	114.174
877.034	113.569
877.865	113.262
878.693	112.96
879.522	112.269
880.35	111.653
881.179	111.28
882.007	111.476
882.836	111.626
883.665	112.123
884.494	112.776
885.32	113.302
886.149	113.313
886.977	113.235
887.805	113.223
888.633	113.184
889.46	113.117
890.288	112.97
891.115	112.762
891.942	113.159
892.77	113.762
893.597	113.82
894.423	113.992
895.251	114.254
896.077	114.437
896.904	114.463
897.73	114.903
898.557	115.543
899.383	116.896
900.21	118.01
901.035	119.965
901.861	121.364
902.688	122.081
903.513	122.853
904.338	123.614
905.163	124.409
905.989	125.117
906.815	126.089
907.64	126.967
908.465	127.987
909.29	129.089
910.115	130.225
910.94	131.277
911.764	132.292
912.589	133.193
913.414	134.079
914.237	135.095
915.061	136.003
915.886	136.777
916.71	137.043
917.533	137.968
918.357	138.982
919.181	139.858
920.004	141.534
920.828	136.335
921.652	142.576
922.474	145.945
923.298	148.001
924.121	149.926
924.943	151.977
925.767	155.092
926.589	158.897
927.411	162.256
928.234	166.181
929.056	170.608
929.878	174.997
930.7	179.416
931.523	183.501
932.345	187.446
933.167	191.554
933.988	195.441
934.81	199.388
935.631	202.921
936.453	206.239
937.274	209.454
938.095	212.671
938.917	215.077
939.736	216.464
940.558	216.808
941.379	216.421
942.2	215.661
943.02	213.879
943.84	211.67
944.661	209.937
945.48	207.889
946.301	206.161
947.121	204.677
947.94	203.322
948.761	202.402
949.58	201.884
950.399	201.668
951.219	201.376
952.038	201.654
952.857	202.121
953.677	202.405
954.495	203.124
955.314	203.669
956.132	203.864
956.952	204.161
957.771	204.58
958.589	205.144
959.407	205.782
960.225	206.526
961.044	207.458
961.862	208.44
962.68	209.356
963.497	210.068
964.314	210.785
965.132	211.546
965.95	212.147
966.767	213.017
967.585	213.821
968.401	214.701
969.218	215.832
970.036	217.189
970.852	218.286
971.669	219.476
972.485	220.759
973.302	221.924
974.118	222.936
974.935	223.62
975.751	223.966
976.566	224.001
977.383	223.629
978.198	222.936
979.014	222.211
979.829	221.451
980.646	220.676
981.461	219.864
982.276	219.071
983.091	218.21
983.906	217.437
984.721	216.472
985.536	214.089
986.35	211.341
987.165	207.808
987.98	204.095
988.794	199.923
989.609	195.635
989.749	195.258
990.587	188.819
991.422	181.302
992.26	175.448
993.095	170.133
993.932	165.855
994.768	162.678
995.605	160.62
996.441	157.09
997.276	153.041
998.113	149.839
998.948	146.693
999.783	143.682